<?xml version="1.0" ?>
<sdf version="1.8">
  <model name="delivery_robot">
    <static>false</static>
    
    <!-- Base link / chassis -->
    <link name="base_link">
      <pose>0 0 0.05 0 0 0</pose>
      
      <inertial>
        <mass>5.0</mass>
        <inertia>
          <ixx>0.083</ixx>
          <ixy>0</ixy>
          <ixz>0</ixz>
          <iyy>0.083</iyy>
          <iyz>0</iyz>
          <izz>0.125</izz>
        </inertia>
      </inertial>
      
      <collision name="base_collision">
        <geometry>
          <box>
            <size>0.4 0.3 0.1</size>
          </box>
        </geometry>
      </collision>
      
      <visual name="base_visual">
        <geometry>
          <box>
            <size>0.4 0.3 0.1</size>
          </box>
        </geometry>
        <material>
          <ambient>0.2 0.2 0.8 1</ambient>
          <diffuse>0.3 0.3 0.9 1</diffuse>
        </material>
      </visual>
    </link>
    
    <!-- Left wheel -->
    <link name="left_wheel">
      <pose>0.0 0.17 0.035 -1.5707963 0 0</pose>
      
      <inertial>
        <mass>0.5</mass>
        <inertia>
          <ixx>0.0005</ixx>
          <ixy>0</ixy>
          <ixz>0</ixz>
          <iyy>0.0005</iyy>
          <iyz>0</iyz>
          <izz>0.001</izz>
        </inertia>
      </inertial>
      
      <collision name="left_wheel_collision">
        <geometry>
          <cylinder>
            <radius>0.035</radius>
            <length>0.025</length>
          </cylinder>
        </geometry>
        <surface>
          <friction>
            <ode>
              <mu>1.0</mu>
              <mu2>1.0</mu2>
            </ode>
          </friction>
        </surface>
      </collision>
      
      <visual name="left_wheel_visual">
        <geometry>
          <cylinder>
            <radius>0.035</radius>
            <length>0.025</length>
          </cylinder>
        </geometry>
        <material>
          <ambient>0.1 0.1 0.1 1</ambient>
          <diffuse>0.2 0.2 0.2 1</diffuse>
        </material>
      </visual>
    </link>
    
    <!-- Right wheel -->
    <link name="right_wheel">
      <pose>0.0 -0.17 0.035 -1.5707963 0 0</pose>
      
      <inertial>
        <mass>0.5</mass>
        <inertia>
          <ixx>0.0005</ixx>
          <ixy>0</ixy>
          <ixz>0</ixz>
          <iyy>0.0005</iyy>
          <iyz>0</iyz>
          <izz>0.001</izz>
        </inertia>
      </inertial>
      
      <collision name="right_wheel_collision">
        <geometry>
          <cylinder>
            <radius>0.035</radius>
            <length>0.025</length>
          </cylinder>
        </geometry>
        <surface>
          <friction>
            <ode>
              <mu>1.0</mu>
              <mu2>1.0</mu2>
            </ode>
          </friction>
        </surface>
      </collision>
      
      <visual name="right_wheel_visual">
        <geometry>
          <cylinder>
            <radius>0.035</radius>
            <length>0.025</length>
          </cylinder>
        </geometry>
        <material>
          <ambient>0.1 0.1 0.1 1</ambient>
          <diffuse>0.2 0.2 0.2 1</diffuse>
        </material>
      </visual>
    </link>
    
    <!-- Caster wheel (front) -->
    <link name="caster_wheel">
      <pose>0.15 0 0.015 0 0 0</pose>
      
      <inertial>
        <mass>0.2</mass>
        <inertia>
          <ixx>0.0001</ixx>
          <ixy>0</ixy>
          <ixz>0</ixz>
          <iyy>0.0001</iyy>
          <iyz>0</iyz>
          <izz>0.0001</izz>
        </inertia>
      </inertial>
      
      <collision name="caster_collision">
        <geometry>
          <sphere>
            <radius>0.015</radius>
          </sphere>
        </geometry>
        <surface>
          <friction>
            <ode>
              <mu>0.01</mu>
              <mu2>0.01</mu2>
            </ode>
          </friction>
        </surface>
      </collision>
      
      <visual name="caster_visual">
        <geometry>
          <sphere>
            <radius>0.015</radius>
          </sphere>
        </geometry>
        <material>
          <ambient>0.5 0.5 0.5 1</ambient>
          <diffuse>0.6 0.6 0.6 1</diffuse>
        </material>
      </visual>
    </link>
    
    <!-- LiDAR sensor link -->
    <link name="lidar_link">
      <pose>0.1 0 0.12 0 0 0</pose>
      
      <inertial>
        <mass>0.2</mass>
        <inertia>
          <ixx>0.0001</ixx>
          <ixy>0</ixy>
          <ixz>0</ixz>
          <iyy>0.0001</iyy>
          <iyz>0</iyz>
          <izz>0.0001</izz>
        </inertia>
      </inertial>
      
      <collision name="lidar_collision">
        <geometry>
          <cylinder>
            <radius>0.04</radius>
            <length>0.04</length>
          </cylinder>
        </geometry>
      </collision>
      
      <visual name="lidar_visual">
        <geometry>
          <cylinder>
            <radius>0.04</radius>
            <length>0.04</length>
          </cylinder>
        </geometry>
        <material>
          <ambient>0.8 0.2 0.2 1</ambient>
          <diffuse>0.9 0.3 0.3 1</diffuse>
        </material>
      </visual>
      
      <!-- 2D LiDAR sensor -->
      <!-- IMPORTANT: Use absolute topic name (starting with /) to avoid Gazebo namespacing -->
      <sensor name="lidar" type="gpu_lidar">
        <always_on>true</always_on>
        <update_rate>10</update_rate>
        <visualize>false</visualize>
        <topic>/scan</topic>
        <lidar>
          <scan>
            <horizontal>
              <samples>360</samples>
              <resolution>1</resolution>
              <min_angle>-3.14159</min_angle>
              <max_angle>3.14159</max_angle>
            </horizontal>
          </scan>
          <range>
            <min>0.12</min>
            <max>10.0</max>
            <resolution>0.01</resolution>
          </range>
          <noise>
            <type>gaussian</type>
            <mean>0.0</mean>
            <stddev>0.01</stddev>
          </noise>
        </lidar>
      </sensor>
    </link>
    
    <!-- Joints -->
    <joint name="left_wheel_joint" type="revolute">
      <parent>base_link</parent>
      <child>left_wheel</child>
      <axis>
        <xyz>0 0 1</xyz>
        <limit>
          <lower>-1e16</lower>
          <upper>1e16</upper>
        </limit>
      </axis>
    </joint>
    
    <joint name="right_wheel_joint" type="revolute">
      <parent>base_link</parent>
      <child>right_wheel</child>
      <axis>
        <xyz>0 0 1</xyz>
        <limit>
          <lower>-1e16</lower>
          <upper>1e16</upper>
        </limit>
      </axis>
    </joint>
    
    <joint name="caster_joint" type="ball">
      <parent>base_link</parent>
      <child>caster_wheel</child>
    </joint>
    
    <joint name="lidar_joint" type="fixed">
      <parent>base_link</parent>
      <child>lidar_link</child>
    </joint>
    
    <!-- Differential drive plugin -->
    <!-- IMPORTANT: Use absolute topic names (starting with /) to avoid Gazebo namespacing -->
    <!-- TF is disabled here - odom_to_tf node handles TF with wall clock timestamps -->
    <plugin filename="gz-sim-diff-drive-system" name="gz::sim::systems::DiffDrive">
      <left_joint>left_wheel_joint</left_joint>
      <right_joint>right_wheel_joint</right_joint>
      <wheel_separation>0.34</wheel_separation>
      <wheel_radius>0.035</wheel_radius>
      <odom_publish_frequency>20</odom_publish_frequency>
      <topic>/cmd_vel</topic>
      <odom_topic>/odom</odom_topic>
      <tf_topic>tf_gazebo_unused</tf_topic>
      <frame_id>odom</frame_id>
      <child_frame_id>base_link</child_frame_id>
    </plugin>
    
    <!-- Joint state publisher -->
    <plugin filename="gz-sim-joint-state-publisher-system" name="gz::sim::systems::JointStatePublisher">
      <topic>/joint_states</topic>
      <joint_name>left_wheel_joint</joint_name>
      <joint_name>right_wheel_joint</joint_name>
    </plugin>
    
    <!-- Delivery package (visual representation) -->
    <link name="delivery_package">
      <pose>0.0 0.0 0.15 0 0 0</pose>
      
      <inertial>
        <mass>0.5</mass>
        <inertia>
          <ixx>0.002</ixx>
          <ixy>0</ixy>
          <ixz>0</ixz>
          <iyy>0.002</iyy>
          <iyz>0</iyz>
          <izz>0.002</izz>
        </inertia>
      </inertial>
      
      <visual name="package_visual">
        <geometry>
          <box>
            <size>0.18 0.14 0.1</size>
          </box>
        </geometry>
        <material>
          <ambient>0.6 0.4 0.2 1</ambient>
          <diffuse>0.8 0.5 0.3 1</diffuse>
        </material>
      </visual>
      
      <!-- Package tape stripes -->
      <visual name="tape_stripe_1">
        <pose>0 0 0.051 0 0 0</pose>
        <geometry>
          <box>
            <size>0.19 0.03 0.001</size>
          </box>
        </geometry>
        <material>
          <ambient>0.6 0.5 0.3 1</ambient>
          <diffuse>0.7 0.6 0.4 1</diffuse>
        </material>
      </visual>
      
      <visual name="tape_stripe_2">
        <pose>0 0 0.051 0 0 1.5708</pose>
        <geometry>
          <box>
            <size>0.15 0.03 0.001</size>
          </box>
        </geometry>
        <material>
          <ambient>0.6 0.5 0.3 1</ambient>
          <diffuse>0.7 0.6 0.4 1</diffuse>
        </material>
      </visual>
    </link>
    
    <joint name="package_joint" type="fixed">
      <parent>base_link</parent>
      <child>delivery_package</child>
    </joint>
    
  </model>
</sdf>

